<?xml version="1.0"?>
<robot xmlns:xacro="http://ros.org/wiki/xacro">
<!-- Macro to load mesh -->
<xacro:macro name="urdf_mesh" params="_filename">
	<geometry>
		<mesh filename="package://riserobotdb/${_filename}" />
	</geometry>
</xacro:macro>
<!-- Macro to load inertial information -->
<xacro:macro name="urdf_inertial" params="_mass _cg _ixx _iyy _izz _ixy _ixz _iyz">
	<inertial>
		<mass value="${_mass}"/>
		<origin xyz="${_cg}"/>
		<inertia ixx="${_ixx}" ixy="${_ixy}" ixz="${_ixz}"
				 iyy="${_iyy}" iyz="${_iyz}"
				 izz="${_izz}"/>
	</inertial>
</xacro:macro>
<!-- Macro of null link in urdf -->
<xacro:macro name="urdf_link_null" params="_name">
	<link name="${_name}">
		<xacro:urdf_inertial _mass="0.01" _cg="0 0 0" _ixx="1" _iyy="1" _izz="1" _ixy="0" _ixz="0" _iyz="0" />
		<visual>
			<origin xyz="0 0 0" rpy="0 0 0" />
			<geometry><box size="0 0 0" /></geometry>
		</visual>
		<collision>
			<origin xyz="0 0 0" rpy="0 0 0" />
			<geometry><box size="0 0 0" /></geometry>
		</collision>
	</link>
</xacro:macro>
<!-- Macro of a link in urdf -->
<xacro:macro name="urdf_link" params="_name _xyz _rpy _mesh _mass _cg _ixx _iyy _izz _ixy _ixz _iyz">
	<link name="${_name}">
		<xacro:urdf_inertial _mass="${_mass}" _cg="${_cg}" _ixx="${_ixx}" 
			_iyy="${_iyy}" _izz="${_izz}" _ixy="${_ixy}" _ixz="${_ixz}" _iyz="${_iyz}" />
		<visual>
			<origin xyz="${_xyz}" rpy="${_rpy}" />
			<xacro:urdf_mesh _filename="${_mesh}" />
		</visual>
		<collision>
			<origin xyz="${_xyz}" rpy="${_rpy}" />
			<xacro:urdf_mesh _filename="${_mesh}" />
		</collision>	
	</link>
</xacro:macro>
<xacro:macro name="urdf_link_color" params="_name _xyz _rpy _mesh _mass _cg _ixx _iyy _izz _ixy _ixz _iyz _colorname _rgba">
	<link name="${_name}">
		<xacro:urdf_inertial _mass="${_mass}" _cg="${_cg}" _ixx="${_ixx}" 
			_iyy="${_iyy}" _izz="${_izz}" _ixy="${_ixy}" _ixz="${_ixz}" _iyz="${_iyz}" />
		<visual>
			<origin xyz="${_xyz}" rpy="${_rpy}" />
			<xacro:urdf_mesh _filename="${_mesh}" />
			<material name="${_colorname}">
				<color rgba="${_rgba}"/>
			</material>			
		</visual>
		<collision>
			<origin xyz="${_xyz}" rpy="${_rpy}" />
			<xacro:urdf_mesh _filename="${_mesh}" />
		</collision>	
	</link>
</xacro:macro>
<!-- Macro of a fixed joint in urdf -->
<xacro:macro name="urdf_fixed_joint" params="_name _parent _child _xyz _rpy">
	<joint name="${_name}" type="fixed">
		<origin xyz="${_xyz}" rpy="${_rpy}"/>
		<parent link="${_parent}" />
		<child link="${_child}" />
	</joint>
</xacro:macro>
<!-- Macro of a revolute joint in urdf -->
<xacro:macro name="urdf_revolute_joint" params="_name _parent _child _axis _xyz _rpy _lower _upper _effort _velocity" >
	<joint name="${_name}" type="revolute">
		<origin xyz="${_xyz}" rpy="${_rpy}"/>
		<parent link="${_parent}" />
		<child link="${_child}" />
		<axis xyz="${_axis}"/>
		<limit lower="${_lower}" upper="${_upper}" effort="${_effort}" velocity="${_velocity}" />
	</joint>
</xacro:macro>
<!-- Macro of a pan tilt joint in urdf -->
<xacro:macro name="urdf_pantilt_joints" params="_name _parent _child1 _child2 _xyz _rpy _lower1 _lower2 _upper1 _upper2 _effort _velocity">
	<xacro:urdf_revolute_joint _name="${_name}_pan_joint" _parent="${_parent}" _child="${_child1}" _axis="0 0 1" _xyz="${_xyz}" _rpy="${_rpy}" _lower="${_lower1}" _upper="${_upper1}" _effort="${_effort}" _velocity="${_velocity}" />
	<xacro:urdf_revolute_joint _name="${_name}_tilt_joint" _parent="${_child1}" _child="${_child2}" _axis="0 1 0" _xyz="0 0 0" _rpy="0 0 0" _lower="${_lower2}" _upper="${_upper2}" _effort="${_effort}" _velocity="${_velocity}"/>
</xacro:macro>
<!-- Macro of a wheel joint in urdf -->
<xacro:macro name="urdf_wheel_joint" params="_name _parent _child _axis _xyz _rpy _effort _velocity" >
	<joint name="${_name}" type="continuous">
		<origin xyz="${_xyz}" rpy="${_rpy}"/>
		<parent link="${_parent}" />
		<child link="${_child}" />
		<axis xyz="${_axis}"/>
		<limit effort="${_effort}" velocity="${_velocity}" />
	</joint>
</xacro:macro>
<!-- Macro of transmission joint controllers -->
<xacro:macro name="urdf_transmission" params="joint id">
	<transmission name="tran${id}">
		<type>transmission_interface/SimpleTransmission</type>
		<joint name="${joint}">
			<hardwareInterface>EffortJointInterface</hardwareInterface>
		</joint>
		<actuator name="motor${id}">
			<hardwareInterface>EffortJointInterface</hardwareInterface>
			<mechanicalReduction>1</mechanicalReduction>
		</actuator>
	</transmission>
</xacro:macro>
</robot>
